<?xml version="1.0" ?>

<!-- inspired from http://www.theconstructsim.com/ros-projects-exploring-ros-using-2-wheeled-robot-part-1/#part1  -->

<robot name="mnwlk3r" xmlns:xacro="https://www.ros.org/wiki/xacro" >
  
  
  <material name="black">
    <color rgba="0.0 0.0 0.0 1.0"/>
  </material>
  <material name="blue">
    <color rgba="0.0 0.0 0.8 1.0"/>
  </material>
  <material name="green">
    <color rgba="0.0 0.8 0.0 1.0"/>
  </material>
  <material name="grey">
    <color rgba="0.25 0.25 0.25 1.0"/>
  </material>
  <material name="orange">
    <color rgba="1.0 0.423529411765 0.0392156862745 1.0"/>
  </material>
  <material name="brown">
    <color rgba="0.870588235294 0.811764705882 0.764705882353 1.0"/>
  </material>
  <material name="red">
    <color rgba="0.80078125 0.12890625 0.1328125 1.0"/>
  </material>
  <material name="white">
    <color rgba="1.0 1.0 1.0 1.0"/>
  </material>  
  
  <gazebo reference="base_footprint">
    <material>Gazebo/Orange</material>
  </gazebo>
  <gazebo reference="link_left_wheel">
    <material>Gazebo/Blue</material>
  </gazebo>
  <gazebo reference="link_right_wheel">
    <material>Gazebo/Blue</material>
  </gazebo>

    <xacro:macro name="cylinder_inertia" params="mass r l">
      <inertia  ixx="${mass*(3*r*r+l*l)/12}" ixy = "0" ixz = "0"
                iyy="${mass*(3*r*r+l*l)/12}" iyz = "0"
                izz="${mass*(r*r)/2}" />
    </xacro:macro>

  
  <link name="base_footprint">
    <!-- pose and inertial -->
    <pose>0 0 0.068 0 0 0</pose>
    <inertial>
      <mass value="5"/>
      <origin xyz="0 0 0.1" rpy="0.0 0 0"  />
      <inertia ixx="0.0395416666667" ixy="0" ixz="0" iyy="0.106208333333" iyz="0" izz="0.106208333333"/>
    </inertial>
    
    <collision name="collision_chassis">
      <origin xyz="0.030 0 0.062" rpy="0 0 0" />
      <geometry>
        <box size="0.400 0.280 0.066"/>
      </geometry>
    </collision>
    
    <visual>
      <origin xyz="0.030 0 0.062" rpy="0 0 0" />  <!-- Z = 29mm offset + half box height = 29 + 66/2 = 62mm   -->
      <geometry>
        <box size="0.400 0.280 0.066"/>
      </geometry>
      <material name="grey"/>
    </visual>
    
    <!-- caster front left (63mm diameter) -->
    <collision name="caster_front_left_collision">
      <!-- Z = - main wheel radius + caster wheel radius = -136/2 + 63/2 = -68 + 31.5 = -36.5mm  -->   
      <origin xyz="0.200 0.070 -0.0365"  rpy=" 0 0 0"  />  
      <geometry>
        <sphere radius="0.0315"/>
      </geometry>
      <surface>
        <friction>
          <ode>
            <mu>0</mu>
            <mu2>0</mu2>
            <slip1>1.0</slip1>
            <slip2>1.0</slip2>
          </ode>
        </friction>
      </surface>
    </collision>
    <visual name="caster_front_left_visual">
      <origin xyz="0.200 0.070 -0.0365"  rpy=" 0 0 0"  />  
      <geometry>
        <sphere radius="0.0315"/>
      </geometry>
    </visual>
    <!-- caster front right  -->
    <collision name="caster_front_right_collision">
      <origin xyz="0.200 -0.070 -0.0365"  rpy=" 0 0 0"  />  
      <geometry>
        <sphere radius="0.0315"/>
      </geometry>
      <surface>
        <friction>
          <ode>
            <mu>0</mu>
            <mu2>0</mu2>
            <slip1>1.0</slip1>
            <slip2>1.0</slip2>
          </ode>
        </friction>
      </surface>
    </collision>
    <visual name="caster_front_right_visual">
      <origin xyz="0.200 -0.070 -0.0365"  rpy=" 0 0 0"  />  
      <geometry>
        <sphere radius="0.0315"/>
      </geometry>
    </visual>
  </link>
  
  <!-- Create wheel right -->  
  <!-- wheel diameter 136mm  |  width 24mm -->    
  <link name="link_right_wheel">    
    <inertial>
      <mass value="0.2"/>
      <origin  xyz="0 0 0" rpy="1.5707 0 0" />  <!-- only 90 deg rotation on X = pi/2 -->
      <inertia ixx="0.00052666666" ixy="0" ixz="0" iyy="0.00052666666" iyz="0" izz="0.001"/>
    </inertial>
    
    <collision name="link_right_wheel_collision">
      <origin  xyz="0 0 0" rpy="1.5707 0 0" />
      <geometry>
        <cylinder length="0.024" radius="0.068"/> 
      </geometry>
    </collision>
    
    <visual name="link_right_wheel_visual">
      <origin  xyz="0 0 0" rpy="1.5707 0 0" />
      <geometry>
        <cylinder length="0.024" radius="0.068"/> 
      </geometry>      
      <material name="green"/>
    </visual>
    
  </link>
    
  <!--   Joint for right wheel  -->
  <joint name="joint_right_wheel" type="continuous">
    <origin xyz="0 -0.164 0" rpy="0 0 0"  /> <!-- X=0  |  Y = half box width + 12m spacer + half wheel width ==> x = -280/2 - 12mm -24/2 = -164mm  -->
    <child link="link_right_wheel" />
    <parent link="base_footprint"/>
    <axis  xyz="0 1 0" rpy="0 0 0" />
    <limit effort="10000" velocity="1000"/>
    <joint_properties damping="1.0" friction="1.0" />
  </joint>  

  
  
  <!-- Create wheel left -->  
  <!-- wheel diameter 136mm  |  width 24mm -->    
  <link name="link_left_wheel">    
    <inertial>
      <mass value="0.2"/>
      <origin  xyz="0 0 0" rpy="1.5707 0 0" />  <!-- only 90 deg rotation on X = pi/2 -->
      <inertia ixx="0.00052666666" ixy="0" ixz="0" iyy="0.00052666666" iyz="0" izz="0.001"/>
    </inertial>
    
    <collision name="link_left_wheel_collision">
      <origin  xyz="0 0 0" rpy="1.5707 0 0" />
      <geometry>
        <cylinder length="0.024" radius="0.068"/> 
      </geometry>
    </collision>
    
    <visual name="link_left_wheel_visual">
      <origin  xyz="0 0 0" rpy="1.5707 0 0" />
      <geometry>
        <cylinder length="0.024" radius="0.068"/> 
      </geometry>      
      <material name="red"/>
    </visual>
    
  </link>
    
  <!--   Joint for left wheel  -->
  <joint name="joint_left_wheel" type="continuous">
    <origin xyz="0 0.164 0" rpy="0 0 0"  /> <!-- X=0  |  Y = half box width + 12m spacer + half wheel width ==> x = -280/2 - 12mm -24/2 = -164mm  -->
    <child link="link_left_wheel" />
    <parent link="base_footprint"/>
    <axis  xyz="0 1 0" rpy="0 0 0" />
    <limit effort="10000" velocity="1000"/>
    <joint_properties damping="1.0" friction="1.0" />
  </joint>  


  
  
   <!--  *** RPLIDAR LASERSCAN ***  -->
   <!--  specs => https://www.slamtec.com/en/Lidar/A2Spec  -->
   <link name="sensor_laser">
    <inertial>
      <origin xyz="0 0 0" rpy="0 0 0" />
      <mass value="1" />
      <!-- this time we use a xacro to calculate inertia  -->
      <xacro:cylinder_inertia mass="0.190" r="0.038" l="0.041" />
    </inertial>

    <visual>
      <origin xyz="0 0 0" rpy="0 0 0" />
      <geometry>
        <cylinder radius="0.038" length="0.041"/>
      </geometry>
      <material name="white" />
    </visual>

    <collision>
      <origin xyz="0 0 0" rpy="0 0 0" />
      <geometry>
        <cylinder radius="0.038" length="0.041"/>
      </geometry>
    </collision>
  </link>

  <joint name="joint_sensor_laser" type="fixed">
    <origin xyz="0.200 0.000 0.110" rpy="0 0 1.5707" />
    <child link="sensor_laser"/>
    <parent link="base_footprint"/>
  </joint>

</robot>
